<2018-10-27 00:18:26,521> <WARNING> sample message
<2018-10-27 00:28:07,098> <ERROR> Exception on /service/123 [GET]
Traceback (most recent call last):
  File "/home/toomas/repo/service_catalogue/venv/lib/python3.6/site-packages/Flask-1.0.2-py3.6.egg/flask/app.py", line 2292, in wsgi_app
    response = self.full_dispatch_request()
  File "/home/toomas/repo/service_catalogue/venv/lib/python3.6/site-packages/Flask-1.0.2-py3.6.egg/flask/app.py", line 1815, in full_dispatch_request
    rv = self.handle_user_exception(e)
  File "/home/toomas/repo/service_catalogue/venv/lib/python3.6/site-packages/Flask-1.0.2-py3.6.egg/flask/app.py", line 1718, in handle_user_exception
    reraise(exc_type, exc_value, tb)
  File "/home/toomas/repo/service_catalogue/venv/lib/python3.6/site-packages/Flask-1.0.2-py3.6.egg/flask/_compat.py", line 35, in reraise
    raise value
  File "/home/toomas/repo/service_catalogue/venv/lib/python3.6/site-packages/Flask-1.0.2-py3.6.egg/flask/app.py", line 1813, in full_dispatch_request
    rv = self.dispatch_request()
  File "/home/toomas/repo/service_catalogue/venv/lib/python3.6/site-packages/Flask-1.0.2-py3.6.egg/flask/app.py", line 1799, in dispatch_request
    return self.view_functions[rule.endpoint](**req.view_args)
  File "/home/toomas/repo/service_catalogue/service_catalogue/web/service.py", line 24, in service_actions
    result = db.service.find({"_id" : ObjectId(serviceId)}),
  File "/home/toomas/repo/service_catalogue/venv/lib/python3.6/site-packages/pymongo-3.7.2-py3.6-linux-x86_64.egg/bson/objectid.py", line 125, in __init__
    self.__validate(oid)
  File "/home/toomas/repo/service_catalogue/venv/lib/python3.6/site-packages/pymongo-3.7.2-py3.6-linux-x86_64.egg/bson/objectid.py", line 221, in __validate
    _raise_invalid_id(oid)
  File "/home/toomas/repo/service_catalogue/venv/lib/python3.6/site-packages/pymongo-3.7.2-py3.6-linux-x86_64.egg/bson/objectid.py", line 67, in _raise_invalid_id
    " or a 24-character hex string" % oid)
bson.errors.InvalidId: '123' is not a valid ObjectId, it must be a 12-byte input or a 24-character hex string
<2018-10-27 00:28:17,854> <ERROR> Exception on /service/5bd38530c979db54f2f076b5 [GET]
Traceback (most recent call last):
  File "/home/toomas/repo/service_catalogue/venv/lib/python3.6/site-packages/Flask-1.0.2-py3.6.egg/flask/app.py", line 1974, in make_response
    rv = self.response_class.force_type(rv, request.environ)
  File "/home/toomas/repo/service_catalogue/venv/lib/python3.6/site-packages/Werkzeug-0.14.1-py3.6.egg/werkzeug/wrappers.py", line 921, in force_type
    response = BaseResponse(*_run_wsgi_app(response, environ))
  File "/home/toomas/repo/service_catalogue/venv/lib/python3.6/site-packages/Werkzeug-0.14.1-py3.6.egg/werkzeug/wrappers.py", line 59, in _run_wsgi_app
    return _run_wsgi_app(*args)
  File "/home/toomas/repo/service_catalogue/venv/lib/python3.6/site-packages/Werkzeug-0.14.1-py3.6.egg/werkzeug/test.py", line 923, in run_wsgi_app
    app_rv = app(environ, start_response)
TypeError: 'dict' object is not callable

During handling of the above exception, another exception occurred:

Traceback (most recent call last):
  File "/home/toomas/repo/service_catalogue/venv/lib/python3.6/site-packages/Flask-1.0.2-py3.6.egg/flask/app.py", line 2292, in wsgi_app
    response = self.full_dispatch_request()
  File "/home/toomas/repo/service_catalogue/venv/lib/python3.6/site-packages/Flask-1.0.2-py3.6.egg/flask/app.py", line 1816, in full_dispatch_request
    return self.finalize_request(rv)
  File "/home/toomas/repo/service_catalogue/venv/lib/python3.6/site-packages/Flask-1.0.2-py3.6.egg/flask/app.py", line 1831, in finalize_request
    response = self.make_response(rv)
  File "/home/toomas/repo/service_catalogue/venv/lib/python3.6/site-packages/Flask-1.0.2-py3.6.egg/flask/app.py", line 1982, in make_response
    reraise(TypeError, new_error, sys.exc_info()[2])
  File "/home/toomas/repo/service_catalogue/venv/lib/python3.6/site-packages/Flask-1.0.2-py3.6.egg/flask/_compat.py", line 34, in reraise
    raise value.with_traceback(tb)
  File "/home/toomas/repo/service_catalogue/venv/lib/python3.6/site-packages/Flask-1.0.2-py3.6.egg/flask/app.py", line 1974, in make_response
    rv = self.response_class.force_type(rv, request.environ)
  File "/home/toomas/repo/service_catalogue/venv/lib/python3.6/site-packages/Werkzeug-0.14.1-py3.6.egg/werkzeug/wrappers.py", line 921, in force_type
    response = BaseResponse(*_run_wsgi_app(response, environ))
  File "/home/toomas/repo/service_catalogue/venv/lib/python3.6/site-packages/Werkzeug-0.14.1-py3.6.egg/werkzeug/wrappers.py", line 59, in _run_wsgi_app
    return _run_wsgi_app(*args)
  File "/home/toomas/repo/service_catalogue/venv/lib/python3.6/site-packages/Werkzeug-0.14.1-py3.6.egg/werkzeug/test.py", line 923, in run_wsgi_app
    app_rv = app(environ, start_response)
TypeError: 'dict' object is not callable
The view function did not return a valid response. The return type must be a string, tuple, Response instance, or WSGI callable, but it was a dict.
<2018-10-27 00:28:24,336> <ERROR> Exception on /service/5bd38530c979db54f2f076b5 [GET]
Traceback (most recent call last):
  File "/home/toomas/repo/service_catalogue/venv/lib/python3.6/site-packages/Flask-1.0.2-py3.6.egg/flask/app.py", line 1974, in make_response
    rv = self.response_class.force_type(rv, request.environ)
  File "/home/toomas/repo/service_catalogue/venv/lib/python3.6/site-packages/Werkzeug-0.14.1-py3.6.egg/werkzeug/wrappers.py", line 921, in force_type
    response = BaseResponse(*_run_wsgi_app(response, environ))
  File "/home/toomas/repo/service_catalogue/venv/lib/python3.6/site-packages/Werkzeug-0.14.1-py3.6.egg/werkzeug/test.py", line 923, in run_wsgi_app
    app_rv = app(environ, start_response)
TypeError: 'dict' object is not callable

During handling of the above exception, another exception occurred:

Traceback (most recent call last):
  File "/home/toomas/repo/service_catalogue/venv/lib/python3.6/site-packages/Flask-1.0.2-py3.6.egg/flask/app.py", line 2292, in wsgi_app
    response = self.full_dispatch_request()
  File "/home/toomas/repo/service_catalogue/venv/lib/python3.6/site-packages/Flask-1.0.2-py3.6.egg/flask/app.py", line 1816, in full_dispatch_request
    return self.finalize_request(rv)
  File "/home/toomas/repo/service_catalogue/venv/lib/python3.6/site-packages/Flask-1.0.2-py3.6.egg/flask/app.py", line 1831, in finalize_request
    response = self.make_response(rv)
  File "/home/toomas/repo/service_catalogue/venv/lib/python3.6/site-packages/Flask-1.0.2-py3.6.egg/flask/app.py", line 1982, in make_response
    reraise(TypeError, new_error, sys.exc_info()[2])
  File "/home/toomas/repo/service_catalogue/venv/lib/python3.6/site-packages/Flask-1.0.2-py3.6.egg/flask/_compat.py", line 34, in reraise
    raise value.with_traceback(tb)
  File "/home/toomas/repo/service_catalogue/venv/lib/python3.6/site-packages/Flask-1.0.2-py3.6.egg/flask/app.py", line 1974, in make_response
    rv = self.response_class.force_type(rv, request.environ)
  File "/home/toomas/repo/service_catalogue/venv/lib/python3.6/site-packages/Werkzeug-0.14.1-py3.6.egg/werkzeug/wrappers.py", line 921, in force_type
    response = BaseResponse(*_run_wsgi_app(response, environ))
  File "/home/toomas/repo/service_catalogue/venv/lib/python3.6/site-packages/Werkzeug-0.14.1-py3.6.egg/werkzeug/test.py", line 923, in run_wsgi_app
    app_rv = app(environ, start_response)
TypeError: 'dict' object is not callable
The view function did not return a valid response. The return type must be a string, tuple, Response instance, or WSGI callable, but it was a dict.
<2018-10-27 00:30:59,982> <ERROR> Exception on /service/5bd38530c979db54f2f076b5 [GET]
Traceback (most recent call last):
  File "/home/toomas/repo/service_catalogue/venv/lib/python3.6/site-packages/Flask-1.0.2-py3.6.egg/flask/app.py", line 2292, in wsgi_app
    response = self.full_dispatch_request()
  File "/home/toomas/repo/service_catalogue/venv/lib/python3.6/site-packages/Flask-1.0.2-py3.6.egg/flask/app.py", line 1815, in full_dispatch_request
    rv = self.handle_user_exception(e)
  File "/home/toomas/repo/service_catalogue/venv/lib/python3.6/site-packages/Flask-1.0.2-py3.6.egg/flask/app.py", line 1718, in handle_user_exception
    reraise(exc_type, exc_value, tb)
  File "/home/toomas/repo/service_catalogue/venv/lib/python3.6/site-packages/Flask-1.0.2-py3.6.egg/flask/_compat.py", line 35, in reraise
    raise value
  File "/home/toomas/repo/service_catalogue/venv/lib/python3.6/site-packages/Flask-1.0.2-py3.6.egg/flask/app.py", line 1813, in full_dispatch_request
    rv = self.dispatch_request()
  File "/home/toomas/repo/service_catalogue/venv/lib/python3.6/site-packages/Flask-1.0.2-py3.6.egg/flask/app.py", line 1799, in dispatch_request
    return self.view_functions[rule.endpoint](**req.view_args)
  File "/home/toomas/repo/service_catalogue/service_catalogue/web/service.py", line 29, in service_actions
    return jsonify(r)
  File "/home/toomas/repo/service_catalogue/venv/lib/python3.6/site-packages/Flask-1.0.2-py3.6.egg/flask/json/__init__.py", line 321, in jsonify
    dumps(data, indent=indent, separators=separators) + '\n',
  File "/home/toomas/repo/service_catalogue/venv/lib/python3.6/site-packages/Flask-1.0.2-py3.6.egg/flask/json/__init__.py", line 179, in dumps
    rv = _json.dumps(obj, **kwargs)
  File "/home/toomas/.pyenv/versions/3.6.3/lib/python3.6/json/__init__.py", line 238, in dumps
    **kw).encode(obj)
  File "/home/toomas/.pyenv/versions/3.6.3/lib/python3.6/json/encoder.py", line 199, in encode
    chunks = self.iterencode(o, _one_shot=True)
  File "/home/toomas/.pyenv/versions/3.6.3/lib/python3.6/json/encoder.py", line 257, in iterencode
    return _iterencode(o, 0)
  File "/home/toomas/repo/service_catalogue/venv/lib/python3.6/site-packages/Flask-1.0.2-py3.6.egg/flask/json/__init__.py", line 81, in default
    return _json.JSONEncoder.default(self, o)
  File "/home/toomas/.pyenv/versions/3.6.3/lib/python3.6/json/encoder.py", line 180, in default
    o.__class__.__name__)
TypeError: Object of type 'Cursor' is not JSON serializable
<2018-10-27 00:32:39,064> <ERROR> Exception on /service/5bd38530c979db54f2f076b5 [GET]
Traceback (most recent call last):
  File "/home/toomas/repo/service_catalogue/venv/lib/python3.6/site-packages/Flask-1.0.2-py3.6.egg/flask/app.py", line 2292, in wsgi_app
    response = self.full_dispatch_request()
  File "/home/toomas/repo/service_catalogue/venv/lib/python3.6/site-packages/Flask-1.0.2-py3.6.egg/flask/app.py", line 1815, in full_dispatch_request
    rv = self.handle_user_exception(e)
  File "/home/toomas/repo/service_catalogue/venv/lib/python3.6/site-packages/Flask-1.0.2-py3.6.egg/flask/app.py", line 1718, in handle_user_exception
    reraise(exc_type, exc_value, tb)
  File "/home/toomas/repo/service_catalogue/venv/lib/python3.6/site-packages/Flask-1.0.2-py3.6.egg/flask/_compat.py", line 35, in reraise
    raise value
  File "/home/toomas/repo/service_catalogue/venv/lib/python3.6/site-packages/Flask-1.0.2-py3.6.egg/flask/app.py", line 1813, in full_dispatch_request
    rv = self.dispatch_request()
  File "/home/toomas/repo/service_catalogue/venv/lib/python3.6/site-packages/Flask-1.0.2-py3.6.egg/flask/app.py", line 1799, in dispatch_request
    return self.view_functions[rule.endpoint](**req.view_args)
  File "/home/toomas/repo/service_catalogue/service_catalogue/web/service.py", line 31, in service_actions
    return jsonify(r)
  File "/home/toomas/repo/service_catalogue/venv/lib/python3.6/site-packages/Flask-1.0.2-py3.6.egg/flask/json/__init__.py", line 321, in jsonify
    dumps(data, indent=indent, separators=separators) + '\n',
  File "/home/toomas/repo/service_catalogue/venv/lib/python3.6/site-packages/Flask-1.0.2-py3.6.egg/flask/json/__init__.py", line 179, in dumps
    rv = _json.dumps(obj, **kwargs)
  File "/home/toomas/.pyenv/versions/3.6.3/lib/python3.6/json/__init__.py", line 238, in dumps
    **kw).encode(obj)
  File "/home/toomas/.pyenv/versions/3.6.3/lib/python3.6/json/encoder.py", line 199, in encode
    chunks = self.iterencode(o, _one_shot=True)
  File "/home/toomas/.pyenv/versions/3.6.3/lib/python3.6/json/encoder.py", line 257, in iterencode
    return _iterencode(o, 0)
  File "/home/toomas/repo/service_catalogue/venv/lib/python3.6/site-packages/Flask-1.0.2-py3.6.egg/flask/json/__init__.py", line 81, in default
    return _json.JSONEncoder.default(self, o)
  File "/home/toomas/.pyenv/versions/3.6.3/lib/python3.6/json/encoder.py", line 180, in default
    o.__class__.__name__)
TypeError: Object of type 'Cursor' is not JSON serializable
<2018-10-27 00:33:49,584> <ERROR> Exception on /service/5bd38530c979db54f2f076b5 [GET]
Traceback (most recent call last):
  File "/home/toomas/repo/service_catalogue/venv/lib/python3.6/site-packages/Flask-1.0.2-py3.6.egg/flask/app.py", line 2292, in wsgi_app
    response = self.full_dispatch_request()
  File "/home/toomas/repo/service_catalogue/venv/lib/python3.6/site-packages/Flask-1.0.2-py3.6.egg/flask/app.py", line 1815, in full_dispatch_request
    rv = self.handle_user_exception(e)
  File "/home/toomas/repo/service_catalogue/venv/lib/python3.6/site-packages/Flask-1.0.2-py3.6.egg/flask/app.py", line 1718, in handle_user_exception
    reraise(exc_type, exc_value, tb)
  File "/home/toomas/repo/service_catalogue/venv/lib/python3.6/site-packages/Flask-1.0.2-py3.6.egg/flask/_compat.py", line 35, in reraise
    raise value
  File "/home/toomas/repo/service_catalogue/venv/lib/python3.6/site-packages/Flask-1.0.2-py3.6.egg/flask/app.py", line 1813, in full_dispatch_request
    rv = self.dispatch_request()
  File "/home/toomas/repo/service_catalogue/venv/lib/python3.6/site-packages/Flask-1.0.2-py3.6.egg/flask/app.py", line 1799, in dispatch_request
    return self.view_functions[rule.endpoint](**req.view_args)
  File "/home/toomas/repo/service_catalogue/service_catalogue/web/service.py", line 32, in service_actions
    return json.dumps(r)
  File "/home/toomas/.pyenv/versions/3.6.3/lib/python3.6/json/__init__.py", line 231, in dumps
    return _default_encoder.encode(obj)
  File "/home/toomas/.pyenv/versions/3.6.3/lib/python3.6/json/encoder.py", line 199, in encode
    chunks = self.iterencode(o, _one_shot=True)
  File "/home/toomas/.pyenv/versions/3.6.3/lib/python3.6/json/encoder.py", line 257, in iterencode
    return _iterencode(o, 0)
  File "/home/toomas/.pyenv/versions/3.6.3/lib/python3.6/json/encoder.py", line 180, in default
    o.__class__.__name__)
TypeError: Object of type 'Cursor' is not JSON serializable
<2018-10-27 00:33:57,825> <ERROR> Exception on /service/5bd38530c979db [GET]
Traceback (most recent call last):
  File "/home/toomas/repo/service_catalogue/venv/lib/python3.6/site-packages/Flask-1.0.2-py3.6.egg/flask/app.py", line 2292, in wsgi_app
    response = self.full_dispatch_request()
  File "/home/toomas/repo/service_catalogue/venv/lib/python3.6/site-packages/Flask-1.0.2-py3.6.egg/flask/app.py", line 1815, in full_dispatch_request
    rv = self.handle_user_exception(e)
  File "/home/toomas/repo/service_catalogue/venv/lib/python3.6/site-packages/Flask-1.0.2-py3.6.egg/flask/app.py", line 1718, in handle_user_exception
    reraise(exc_type, exc_value, tb)
  File "/home/toomas/repo/service_catalogue/venv/lib/python3.6/site-packages/Flask-1.0.2-py3.6.egg/flask/_compat.py", line 35, in reraise
    raise value
  File "/home/toomas/repo/service_catalogue/venv/lib/python3.6/site-packages/Flask-1.0.2-py3.6.egg/flask/app.py", line 1813, in full_dispatch_request
    rv = self.dispatch_request()
  File "/home/toomas/repo/service_catalogue/venv/lib/python3.6/site-packages/Flask-1.0.2-py3.6.egg/flask/app.py", line 1799, in dispatch_request
    return self.view_functions[rule.endpoint](**req.view_args)
  File "/home/toomas/repo/service_catalogue/service_catalogue/web/service.py", line 25, in service_actions
    result = db.service.find({"_id" : ObjectId(serviceId)})
  File "/home/toomas/repo/service_catalogue/venv/lib/python3.6/site-packages/pymongo-3.7.2-py3.6-linux-x86_64.egg/bson/objectid.py", line 125, in __init__
    self.__validate(oid)
  File "/home/toomas/repo/service_catalogue/venv/lib/python3.6/site-packages/pymongo-3.7.2-py3.6-linux-x86_64.egg/bson/objectid.py", line 221, in __validate
    _raise_invalid_id(oid)
  File "/home/toomas/repo/service_catalogue/venv/lib/python3.6/site-packages/pymongo-3.7.2-py3.6-linux-x86_64.egg/bson/objectid.py", line 67, in _raise_invalid_id
    " or a 24-character hex string" % oid)
bson.errors.InvalidId: '5bd38530c979db' is not a valid ObjectId, it must be a 12-byte input or a 24-character hex string
<2018-10-27 00:34:06,288> <ERROR> Exception on /service/5bd38530c979db54f2f076b5 [GET]
Traceback (most recent call last):
  File "/home/toomas/repo/service_catalogue/venv/lib/python3.6/site-packages/Flask-1.0.2-py3.6.egg/flask/app.py", line 2292, in wsgi_app
    response = self.full_dispatch_request()
  File "/home/toomas/repo/service_catalogue/venv/lib/python3.6/site-packages/Flask-1.0.2-py3.6.egg/flask/app.py", line 1815, in full_dispatch_request
    rv = self.handle_user_exception(e)
  File "/home/toomas/repo/service_catalogue/venv/lib/python3.6/site-packages/Flask-1.0.2-py3.6.egg/flask/app.py", line 1718, in handle_user_exception
    reraise(exc_type, exc_value, tb)
  File "/home/toomas/repo/service_catalogue/venv/lib/python3.6/site-packages/Flask-1.0.2-py3.6.egg/flask/_compat.py", line 35, in reraise
    raise value
  File "/home/toomas/repo/service_catalogue/venv/lib/python3.6/site-packages/Flask-1.0.2-py3.6.egg/flask/app.py", line 1813, in full_dispatch_request
    rv = self.dispatch_request()
  File "/home/toomas/repo/service_catalogue/venv/lib/python3.6/site-packages/Flask-1.0.2-py3.6.egg/flask/app.py", line 1799, in dispatch_request
    return self.view_functions[rule.endpoint](**req.view_args)
  File "/home/toomas/repo/service_catalogue/service_catalogue/web/service.py", line 32, in service_actions
    return json.dumps(r)
  File "/home/toomas/.pyenv/versions/3.6.3/lib/python3.6/json/__init__.py", line 231, in dumps
    return _default_encoder.encode(obj)
  File "/home/toomas/.pyenv/versions/3.6.3/lib/python3.6/json/encoder.py", line 199, in encode
    chunks = self.iterencode(o, _one_shot=True)
  File "/home/toomas/.pyenv/versions/3.6.3/lib/python3.6/json/encoder.py", line 257, in iterencode
    return _iterencode(o, 0)
  File "/home/toomas/.pyenv/versions/3.6.3/lib/python3.6/json/encoder.py", line 180, in default
    o.__class__.__name__)
TypeError: Object of type 'Cursor' is not JSON serializable
<2018-10-27 00:37:23,304> <ERROR> Exception on /service/5bd38530c979db54f2f076b5 [GET]
Traceback (most recent call last):
  File "/home/toomas/repo/service_catalogue/venv/lib/python3.6/site-packages/Flask-1.0.2-py3.6.egg/flask/app.py", line 2292, in wsgi_app
    response = self.full_dispatch_request()
  File "/home/toomas/repo/service_catalogue/venv/lib/python3.6/site-packages/Flask-1.0.2-py3.6.egg/flask/app.py", line 1815, in full_dispatch_request
    rv = self.handle_user_exception(e)
  File "/home/toomas/repo/service_catalogue/venv/lib/python3.6/site-packages/Flask-1.0.2-py3.6.egg/flask/app.py", line 1718, in handle_user_exception
    reraise(exc_type, exc_value, tb)
  File "/home/toomas/repo/service_catalogue/venv/lib/python3.6/site-packages/Flask-1.0.2-py3.6.egg/flask/_compat.py", line 35, in reraise
    raise value
  File "/home/toomas/repo/service_catalogue/venv/lib/python3.6/site-packages/Flask-1.0.2-py3.6.egg/flask/app.py", line 1813, in full_dispatch_request
    rv = self.dispatch_request()
  File "/home/toomas/repo/service_catalogue/venv/lib/python3.6/site-packages/Flask-1.0.2-py3.6.egg/flask/app.py", line 1799, in dispatch_request
    return self.view_functions[rule.endpoint](**req.view_args)
  File "/home/toomas/repo/service_catalogue/service_catalogue/web/service.py", line 31, in service_actions
    return json.dumps(r)
  File "/home/toomas/.pyenv/versions/3.6.3/lib/python3.6/json/__init__.py", line 231, in dumps
    return _default_encoder.encode(obj)
  File "/home/toomas/.pyenv/versions/3.6.3/lib/python3.6/json/encoder.py", line 199, in encode
    chunks = self.iterencode(o, _one_shot=True)
  File "/home/toomas/.pyenv/versions/3.6.3/lib/python3.6/json/encoder.py", line 257, in iterencode
    return _iterencode(o, 0)
  File "/home/toomas/.pyenv/versions/3.6.3/lib/python3.6/json/encoder.py", line 180, in default
    o.__class__.__name__)
TypeError: Object of type 'ObjectId' is not JSON serializable
<2018-10-27 00:41:11,438> <ERROR> Exception on /service/5bd38530c979db54f2f076b5 [GET]
Traceback (most recent call last):
  File "/home/toomas/repo/service_catalogue/venv/lib/python3.6/site-packages/Flask-1.0.2-py3.6.egg/flask/app.py", line 2292, in wsgi_app
    response = self.full_dispatch_request()
  File "/home/toomas/repo/service_catalogue/venv/lib/python3.6/site-packages/Flask-1.0.2-py3.6.egg/flask/app.py", line 1815, in full_dispatch_request
    rv = self.handle_user_exception(e)
  File "/home/toomas/repo/service_catalogue/venv/lib/python3.6/site-packages/Flask-1.0.2-py3.6.egg/flask/app.py", line 1718, in handle_user_exception
    reraise(exc_type, exc_value, tb)
  File "/home/toomas/repo/service_catalogue/venv/lib/python3.6/site-packages/Flask-1.0.2-py3.6.egg/flask/_compat.py", line 35, in reraise
    raise value
  File "/home/toomas/repo/service_catalogue/venv/lib/python3.6/site-packages/Flask-1.0.2-py3.6.egg/flask/app.py", line 1813, in full_dispatch_request
    rv = self.dispatch_request()
  File "/home/toomas/repo/service_catalogue/venv/lib/python3.6/site-packages/Flask-1.0.2-py3.6.egg/flask/app.py", line 1799, in dispatch_request
    return self.view_functions[rule.endpoint](**req.view_args)
  File "/home/toomas/repo/service_catalogue/service_catalogue/web/service.py", line 33, in service_actions
    return json.dumps(r)
  File "/home/toomas/.pyenv/versions/3.6.3/lib/python3.6/json/__init__.py", line 231, in dumps
    return _default_encoder.encode(obj)
  File "/home/toomas/.pyenv/versions/3.6.3/lib/python3.6/json/encoder.py", line 199, in encode
    chunks = self.iterencode(o, _one_shot=True)
  File "/home/toomas/.pyenv/versions/3.6.3/lib/python3.6/json/encoder.py", line 257, in iterencode
    return _iterencode(o, 0)
  File "/home/toomas/.pyenv/versions/3.6.3/lib/python3.6/json/encoder.py", line 180, in default
    o.__class__.__name__)
TypeError: Object of type 'ObjectId' is not JSON serializable
<2018-10-27 00:44:52,813> <ERROR> Exception on /service/5bd38530c979db54f2f076b5 [GET]
Traceback (most recent call last):
  File "/home/toomas/repo/service_catalogue/venv/lib/python3.6/site-packages/Flask-1.0.2-py3.6.egg/flask/app.py", line 2292, in wsgi_app
    response = self.full_dispatch_request()
  File "/home/toomas/repo/service_catalogue/venv/lib/python3.6/site-packages/Flask-1.0.2-py3.6.egg/flask/app.py", line 1815, in full_dispatch_request
    rv = self.handle_user_exception(e)
  File "/home/toomas/repo/service_catalogue/venv/lib/python3.6/site-packages/Flask-1.0.2-py3.6.egg/flask/app.py", line 1718, in handle_user_exception
    reraise(exc_type, exc_value, tb)
  File "/home/toomas/repo/service_catalogue/venv/lib/python3.6/site-packages/Flask-1.0.2-py3.6.egg/flask/_compat.py", line 35, in reraise
    raise value
  File "/home/toomas/repo/service_catalogue/venv/lib/python3.6/site-packages/Flask-1.0.2-py3.6.egg/flask/app.py", line 1813, in full_dispatch_request
    rv = self.dispatch_request()
  File "/home/toomas/repo/service_catalogue/venv/lib/python3.6/site-packages/Flask-1.0.2-py3.6.egg/flask/app.py", line 1799, in dispatch_request
    return self.view_functions[rule.endpoint](**req.view_args)
  File "/home/toomas/repo/service_catalogue/service_catalogue/web/service.py", line 41, in service_actions
    return json.encode(r, cls=JsonEncoder)
AttributeError: module 'json' has no attribute 'encode'
